Workbook
Name hoy: TODAY()
Name hoy: TODAY()
Name hoy: TODAY()
Name Inicio_del_proyecto: 'Proyecto Datos (Actual)'!$E$3
Name Inicio_del_proyecto: 'Proyecto Datos (OKR´s)'!$K$3
Name Inicio_del_proyecto: 'Proyecto Datos'!$E$3
Name Semana_para_mostrar: 'Proyecto Datos (Actual)'!$E$4
Name Semana_para_mostrar: 'Proyecto Datos (OKR´s)'!$K$4
Name Semana_para_mostrar: 'Proyecto Datos'!$E$4
Name task_end: 'Proyecto Datos'!$F1
Name task_end: 'Proyecto Datos (Actual)'!$F1
Name task_end: 'Proyecto Datos (OKR´s)'!$L1
Name task_progress: 'Proyecto Datos'!$D1
Name task_progress: 'Proyecto Datos (Actual)'!$D1
Name task_progress: 'Proyecto Datos (OKR´s)'!$J1
Name task_start: 'Proyecto Datos'!$E1
Name task_start: 'Proyecto Datos (Actual)'!$E1
Name task_start: 'Proyecto Datos (OKR´s)'!$K1

Sheet Proyecto Datos (OKR´s)
A1: Cree una programación para un proyecto en esta hoja de cálculo. Escriba el título de este proyecto en la celda B1. Para obtener información sobre cómo usar esta hoja de cálculo, incluidas las instrucciones para lectores de pantalla y el nombre del autor de este libro, vea la hoja de cálculo Información. Desplácese hacia abajo por la columna A para escuchar más instrucciones. | G1: Proyecto Datos Op. Complejas
A2: Escriba el nombre de la compañía en la celda B2. | G2: IHSA S.A.
A3: Escriba el nombre del responsable del proyecto en la celda B3. Escriba la fecha de comienzo del proyecto en la celda E3. Inicio del proyecto: la etiqueta se encuentra en la celda C3. | G3: Santiago Alonso | I3: Inicio del proyecto: | K3: 45958
A4: La semana que se muestra en la celda E4 representa la semana inicial para mostrar en la programación del proyecto en la celda I4. La fecha de inicio del proyecto se considera la semana 1. Para cambiar semana que se muestra, simplemente escriba un número de semana nuevo en la celda E4. La fecha de inicio de cada semana, comenzando por la semana mostrada en la celda E4, comienza en la celda I4 y se calcula automáticamente. Hay 8 semanas representadas en esta vista desde la celda I4 hasta la celda BF4. No debería modificar estas celdas. La etiqueta de la semana para mostrar se encuentra en la celda C4. | I4: Semana para mostrar: | K4: 32 | O4: =O5 -> 46174 | V4: =V5 -> 46181 | AC4: =AC5 -> 46188 | AJ4: =AJ5 -> 46195 | AQ4: =AQ5 -> 46202 | AX4: =AX5 -> 46209 | BE4: =BE5 -> 46216 | BL4: =BL5 -> 46223
A5: Las celdas I5 a BL5 contienen el número de días de la semana representado en el bloque de celdas encima de cada celda de fecha y se calculan automáticamente. No debería modificar estas celdas. La fecha actual está rodeada con una línea roja (hex. AD3815) desde la fecha actual en la fila 5 hasta toda la columna de fechas y el fin de la programación del proyecto. | O5: =Inicio_del_proyecto-WEEKDAY(Inicio_del_proyecto,1)+2+7*(Semana_para_mostrar-1) -> 46174 | P5: =O5+1 -> 46175 | Q5: =P5+1 -> 46176 | R5: =Q5+1 -> 46177 | S5: =R5+1 -> 46178 | T5: =S5+1 -> 46179 | U5: =T5+1 -> 46180 | V5: =U5+1 -> 46181 | W5: =V5+1 -> 46182 | ... BR5: =BQ5+1 -> 46229
A6: Esta fila contiene los encabezados de la programación del proyecto posterior debajo de estos. Navegue desde la celda B6 a BL 6 para escuchar el contenido. La primera letra de cada día de la semana de la fecha encima de ese encabezado empieza en la celda I6 y continúa hasta la celda BL6. Todo el gráficos de escala de tiempo del proyecto está generados automáticamente en función de las fechas de inicio y finalización especificadas, con formatos condicionales. No modifique el contenido de las celdas en las columnas después de la columna I comenzando por la celda I7. | B6: Fecha Reunón Programada | C6: Comentarios | D6: Periodicidad | E6: Sprint | F6: Fecha | G6: TAREA | H6: Ponderación OKR | I6: ASIGNADO A | J6: PROGRESO | K6: INICIO | L6: FIN | N6: DÍAS | O6: =LEFT(TEXT(O5,"ddd"),1) -> l | P6: =LEFT(TEXT(P5,"ddd"),1) -> m | Q6: =LEFT(TEXT(Q5,"ddd"),1) -> m | R6: =LEFT(TEXT(R5,"ddd"),1) -> j | S6: =LEFT(TEXT(S5,"ddd"),1) -> v | T6: =LEFT(TEXT(T5,"ddd"),1) -> s | U6: =LEFT(TEXT(U5,"ddd"),1) -> d | V6: =LEFT(TEXT(V5,"ddd"),1) -> l | ... BR6: =LEFT(TEXT(BR5,"ddd"),1) -> d
A7: La celda B8 contiene el título de ejemplo de la Fase 1. Escriba un nuevo título en la celda B8. Escriba un nombre para asignar la fase, si se aplica para el proyecto, en la celda C8. Escriba el progreso de la fase completa, si se aplica para el proyecto, en la celda D8. Escriba las fechas de inicio y finalización de la fase completa, si se aplica para el proyecto, en las celdas E8 y F8. El gráfico de Gantt rellena automáticamente las fechas adecuadas y aplica un sombreado según el progreso especificado. Para eliminar la fase y trabajar solo con las tareas, elimine esta fila. | G7: 1- GOC: Módulo de Datos para Procesos de Certificación (Inteligencia Comercial) | H7: 0.4 | J7: =+AVERAGE(J8:J8) -> 0.2 | K7: Días Transcurridos= | L7: =TODAY()-MIN(K8)-139 -> 95
A8: La celda B9 contiene la tarea de ejemplo "Tarea 1". Escriba un nuevo nombre de tarea en la celda B9. Escriba una persona a la que asignar la tarea en la celda C9. Escriba el progreso de la tarea en la celda D9. Aparece una barra de progreso en la celda y se sombrea según el número de la celda. Por ejemplo, un progreso del 50 por ciento aplicaría sombreado a la mitad de la celda. Escriba la fecha de inicio de la tarea en la celda E9. Escriba la fecha de finalización de la tarea en la celda F9. Aparece una barra de estado con sombreado para las fechas especificadas en bloques comenzando desde la celda I9 hasta la BL9. | C8: Ok registro global Personas y Móviles (Habilitado/ Inhabilitado/ Dado de baja) + Vencimientos; Próximo: Diagrama (30/6 fecha estimada); Se avanzó con módulo diagrama. | D8: Mensual | E8: 1 | F8: 46203 | G8: Disponibilidad de información centralizada en GOC (aguarda desarrollo) | I8: Lucila Pronzato | J8: 0.2 | K8: =Inicio_del_proyecto -> 45958 | L8: =IF(F8="",WORKDAY(L7,5),F8) -> 46203 | N8: =IF(OR(ISBLANK(task_start),ISBLANK(task_end)),"",task_end-task_start+1) -> 246
A9: La celda a la derecha contiene el título de ejemplo de la Fase 2. Puede crear una nueva fase en cualquier momento en la columna B. Esta programación de proyecto no necesita fases. Para quitar la fase, basta con eliminar la fila. Para crear un bloque de fase nuevo en esta fila, escriba un nuevo título en la celda a la derecha. Para continuar agregando tareas a la fase anterior, escriba una nueva fila encima de esta y rellene los datos de la tarea como se explica en la celda A9. Actualice los detalles de la fase en la celda a la derecha como se explica en la celda A8. Continúe navegando por las celdas de la columna A para obtener más información. Si no ha agregado nuevas filas en esta hoja de cálculo, verá que se han creado automáticamente 2 bloques de fase de ejemplo adicionales en las celdas B20 y B26. En caso contrario, desplácese por las celdas de la columna A para buscar los bloques adicionales. Repita las instrucciones de las celdas A8 y A9 cuando lo necesite. | G9: 2- Cotizador de Operaciones Complejas | H9: 0.35 | J9: =+AVERAGE(J10:J19) -> 0.58 | K9: =+$K$7 -> Días Transcurridos= | L9: =TODAY()-MIN(K10:K21)-139 -> 95
D10: Quincenal | E10: 1 | F10: 46192 | G10: Crear estructura de Cotizador en base a modelo armado (migra a CLAUDE) | I10: Santiago Alonso | J10: 1 | K10: 45958 | L10: =IF(F10="",WORKDAY(L9,5),F10) -> 46192 | N10: =IF(OR(ISBLANK(task_start),ISBLANK(task_end)),"",task_end-task_start+1) -> 235
B11: Martes 16/06 | C11: Reunión con Danna Mar 16/06; dependo de tiempos de Danna. Se avanzó pero falta ya que estamos realizando una automatización linea por linea. | D11: =+$D$10 -> Quincenal | E11: 1 | F11: 46192 | G11: Automatización Archivo Sueldos FATSA + Procedimientos | I11: Santiago Alonso | J11: 0.75 | K11: 45958 | L11: =IF(F11="",WORKDAY(L10,5),F11) -> 46192 | N11: =IF(OR(ISBLANK(task_start),ISBLANK(task_end)),"",task_end-task_start+1) -> 235
D12: =+$D$10 -> Quincenal | E12: 1 | F12: 46192 | G12: Automatización Archivo Sueldos Petro + Procedimientos | I12: Santiago Alonso | J12: 0.75 | K12: 45978 | L12: =IF(F12="",WORKDAY(L11,5),F12) -> 46192 | N12: =IF(OR(ISBLANK(task_start),ISBLANK(task_end)),"",task_end-task_start+1) -> 215
C13: pedir últimos a Carlos Hernández; no llegué | D13: =+$D$10 -> Quincenal | E13: 1 | F13: 46192 | G13: Relevamiento Últimos Sueldos de referencia Monotributistas | I13: Santiago Alonso | J13: 0.5 | K13: 46345 | L13: =IF(F13="",WORKDAY(L12,5),F13) -> 46192
D14: =+$D$10 -> Quincenal | G14: Estandarización cotizaciones COMPRAS (costos x provincia) - aguardo información | I14: Santiago Alonso | J14: 0.2 | K14: 45959 | L14: =IF(F14="",WORKDAY(L13,5),F14) -> 46199 | N14: =IF(OR(ISBLANK(task_start),ISBLANK(task_end)),"",task_end-task_start+1) -> 241
C15: Avance Nico Sifuentes; sólo pendiente procedimiento. | D15: =+$D$10 -> Quincenal | E15: 1 | F15: 46192 | G15: Asociar Archivo Móviles y Tráilers (Nico Sifuentes) + procedimiento | I15: Santiago Alonso | J15: 0.95 | K15: 45992 | L15: =IF(F15="",WORKDAY(L14,5),F15) -> 46192 | N15: =IF(OR(ISBLANK(task_start),ISBLANK(task_end)),"",task_end-task_start+1) -> 201
B16: Jueves 11/06 | C16: Reunión jue 11/6 - Avance Seba Oliver; sólo pendiente procedimiento. | D16: =+$D$10 -> Quincenal | E16: 1 | F16: 46192 | G16: Asociar Archivo Masters de Medicación (Seba Oliver) + Capacitaciones + procedimiento | I16: Santiago Alonso | J16: 0.65 | K16: 45992 | L16: =IF(F16="",WORKDAY(L15,5),F16) -> 46192 | N16: =IF(OR(ISBLANK(task_start),ISBLANK(task_end)),"",task_end-task_start+1) -> 201
C17: Revisar con Fran | D17: =+$D$10 -> Quincenal | G17: Asociar Gastos de Estructura (% de incidencia) | I17: Santiago Alonso | J17: 0 | K17: =+L14+1 -> 46200 | L17: =IF(F17="",WORKDAY(MAX(L10:L16),5),F17) -> 46206 | N17: =IF(OR(ISBLANK(task_start),ISBLANK(task_end)),"",task_end-task_start+1) -> 7
D18: =+$D$10 -> Quincenal | G18: Armado de solicitudes extra x Módulos (Ej: Med. Laboral) | I18: Santiago Alonso | J18: 0 | K18: =+L12+1 -> 46193 | L18: =IF(F18="",WORKDAY(MAX(L11:L17),5),F18) -> 46213 | N18: =IF(OR(ISBLANK(task_start),ISBLANK(task_end)),"",task_end-task_start+1) -> 21
B19: Martes 09/06 | C19: mar 9/6 Reunión Torres, Huilen (Equipo IA) - Definir con Nico Vazquez. En reunión se definió que una vez finalizado el proyecto, el backend, seguridad y deploy lo continúan en IT. | D19: =+$D$10 -> Quincenal | E19: 1 | F19: 46192 | G19: Relevamiento área de IA - Repositorio (GitHub o AWS S3) + Seguridad | I19: Santiago Alonso | J19: 1 | K19: 46182 | L19: =IF(F19="",WORKDAY(MAX(L10:L18),5),F19) -> 46192 | N19: =IF(OR(ISBLANK(task_start),ISBLANK(task_end)),"",task_end-task_start+1) -> 11
D20: =+$D$10 -> Quincenal | G20: Crear Backend ETL - ver con Claude Code | I20: Santiago Alonso | J20: 0 | K20: =+L19+1 -> 46193 | L20: =IF(F20="",WORKDAY(MAX(L13:L19),5),F20) -> 46220 | N20: =IF(OR(ISBLANK(task_start),ISBLANK(task_end)),"",task_end-task_start+1) -> 28
D21: =+$D$10 -> Quincenal | G21: Deployar (URL Web) | I21: Santiago Alonso | J21: 0 | K21: =+L20+1 -> 46221 | L21: =IF(F21="",WORKDAY(MAX(L14:L20),5),F21) -> 46227 | N21: =IF(OR(ISBLANK(task_start),ISBLANK(task_end)),"",task_end-task_start+1) -> 7
A22: Bloque de título fase de ejemplo | G22: 3- Tablero BI OPEX - Real vs BO | H22: 0.25 | J22: =+AVERAGE(J23:J26) -> 0.875 | K22: =+$K$7 -> Días Transcurridos= | L22: =TODAY()-MIN(K23:K26) -> 15
A23: Las filas de la 10 a la 13 repiten el patrón de la fila 9. Repita las instrucciones de la celda A9 para todas las filas de tareas en esta hoja de cálculo. Sobrescriba los datos de ejemplo. Un ejemplo de otra fase empieza en la celda A14. Continue escribiendo tareas en las celdas de la A10 a la A13 o vaya a la celda A14 para obtener más información. | D23: Semanal | E23: 1 | F23: 46192 | G23: Armado de Procedimiento | I23: Santiago Alonso | J23: 0.9 | K23: 46182 | L23: =IF(F23="",WORKDAY(L22,5),F23) -> 46192 | N23: =IF(OR(ISBLANK(task_start),ISBLANK(task_end)),"",task_end-task_start+1) -> 11
A24: Las filas de la 10 a la 13 repiten el patrón de la fila 9. Repita las instrucciones de la celda A9 para todas las filas de tareas en esta hoja de cálculo. Sobrescriba los datos de ejemplo. Un ejemplo de otra fase empieza en la celda A14. Continue escribiendo tareas en las celdas de la A10 a la A13 o vaya a la celda A14 para obtener más información. | D24: =+$D$23 -> Semanal | E24: 1 | F24: 46192 | G24: Revisión de Gráfico en cascada: por desvío y desagregación por categorías. | I24: Santiago Alonso | J24: 0.9 | K24: 46177 | L24: =IF(F24="",WORKDAY(MAX(L23:L26),5),F24) -> 46192 | N24: =IF(OR(ISBLANK(task_start),ISBLANK(task_end)),"",task_end-task_start+1) -> 16
A25: Las filas de la 10 a la 13 repiten el patrón de la fila 9. Repita las instrucciones de la celda A9 para todas las filas de tareas en esta hoja de cálculo. Sobrescriba los datos de ejemplo. Un ejemplo de otra fase empieza en la celda A14. Continue escribiendo tareas en las celdas de la A10 a la A13 o vaya a la celda A14 para obtener más información. | D25: =+$D$23 -> Semanal | E25: 1 | F25: 46185 | G25: Revisión de viabilidad de incorporación datos Redash (input ZReal con clasificaciones automaticas por CECO - Directas e Indirectas) | I25: Santiago Alonso | J25: 0.9 | K25: 46177 | L25: =IF(F25="",WORKDAY(MAX($L$23:$L$26),5),F25) -> 46185 | N25: =IF(OR(ISBLANK(task_start),ISBLANK(task_end)),"",task_end-task_start+1) -> 9
A26: Las filas de la 10 a la 13 repiten el patrón de la fila 9. Repita las instrucciones de la celda A9 para todas las filas de tareas en esta hoja de cálculo. Sobrescriba los datos de ejemplo. Un ejemplo de otra fase empieza en la celda A14. Continue escribiendo tareas en las celdas de la A10 a la A13 o vaya a la celda A14 para obtener más información. | G26: Revisión y Publicación de Tablero | I26: Santiago Alonso | J26: 0.8 | K26: 46185 | L26: =IF(F26="",WORKDAY(MAX($L$23:$L$25),5),F26) -> 46199 | N26: =IF(OR(ISBLANK(task_start),ISBLANK(task_end)),"",task_end-task_start+1) -> 15
A27: Bloque de título fase de ejemplo | G27: 4- Tablero BI DEUDA | J27: =+AVERAGE(J39:J49) -> 0.37575758 | K27: =+$K$7 -> Días Transcurridos= | L27: =TODAY()-MIN(K28:K35)-139 -> 61
A28: Las filas de la 10 a la 13 repiten el patrón de la fila 9. Repita las instrucciones de la celda A9 para todas las filas de tareas en esta hoja de cálculo. Sobrescriba los datos de ejemplo. Un ejemplo de otra fase empieza en la celda A14. Continue escribiendo tareas en las celdas de la A10 a la A13 o vaya a la celda A14 para obtener más información. | D28: Semanal | E28: 1 | F28: 46185 | G28: Procedimiento | I28: Santiago Alonso | J28: 0.9 | K28: 46181 | L28: =IF(F28="",WORKDAY(L27,5),F28) -> 46185 | N28: =IF(OR(ISBLANK(task_start),ISBLANK(task_end)),"",task_end-task_start+1) -> 5
A29: Las filas de la 10 a la 13 repiten el patrón de la fila 9. Repita las instrucciones de la celda A9 para todas las filas de tareas en esta hoja de cálculo. Sobrescriba los datos de ejemplo. Un ejemplo de otra fase empieza en la celda A14. Continue escribiendo tareas en las celdas de la A10 a la A13 o vaya a la celda A14 para obtener más información. | D29: =+$D$28 -> Semanal | E29: 1 | F29: 46185 | G29: Aging - desde SharePoint | I29: Santiago Alonso | J29: 0.9 | K29: 45992 | L29: =IF(F29="",WORKDAY(L28,5),F29) -> 46185 | N29: =IF(OR(ISBLANK(task_start),ISBLANK(task_end)),"",task_end-task_start+1) -> 194
A30: Las filas de la 10 a la 13 repiten el patrón de la fila 9. Repita las instrucciones de la celda A9 para todas las filas de tareas en esta hoja de cálculo. Sobrescriba los datos de ejemplo. Un ejemplo de otra fase empieza en la celda A14. Continue escribiendo tareas en las celdas de la A10 a la A13 o vaya a la celda A14 para obtener más información. | D30: =+$D$28 -> Semanal | E30: 1 | F30: 46185 | G30: Dias en Calle - desde SharePoint | I30: Santiago Alonso | J30: 0.9 | K30: 45992 | L30: =IF(F30="",WORKDAY(L29,5),F30) -> 46185 | N30: =IF(OR(ISBLANK(task_start),ISBLANK(task_end)),"",task_end-task_start+1) -> 194
A31: Las filas de la 10 a la 13 repiten el patrón de la fila 9. Repita las instrucciones de la celda A9 para todas las filas de tareas en esta hoja de cálculo. Sobrescriba los datos de ejemplo. Un ejemplo de otra fase empieza en la celda A14. Continue escribiendo tareas en las celdas de la A10 a la A13 o vaya a la celda A14 para obtener más información. | D31: =+$D$28 -> Semanal | E31: 1 | F31: 46185 | G31: Input de datos desde Provisión mensual | I31: Santiago Alonso | J31: 0.9 | K31: 46023 | L31: =IF(F31="",WORKDAY(L30,5),F31) -> 46185 | N31: =IF(OR(ISBLANK(task_start),ISBLANK(task_end)),"",task_end-task_start+1) -> 163
D32: =+$D$28 -> Semanal | G32: Analizar viabilidad de input Redash: Importe Provisionado (Datalake --> Clik Sense) | I32: Santiago Alonso | J32: 0.6 | K32: 46188 | L32: =IF(F32="",WORKDAY(L30,5),F32) -> 46192 | N32: =IF(OR(ISBLANK(task_start),ISBLANK(task_end)),"",task_end-task_start+1) -> 5
D33: =+$D$28 -> Semanal | G33: Analizar viabilidad de input Redash: Importe Facturado (Datalake --> Clik Sense "Venta Bruta") | I33: Santiago Alonso | J33: 0.6 | K33: 46192 | L33: =IF(F33="",WORKDAY(L32,5),F33) -> 46199 | N33: =IF(OR(ISBLANK(task_start),ISBLANK(task_end)),"",task_end-task_start+1) -> 8
D34: =+$D$28 -> Semanal | G34: Creación detalle deuda Vista - Replicar Excel Deuda | I34: Santiago Alonso | J34: 0.5 | K34: 46188 | L34: =IF(F34="",WORKDAY(L32,5),F34) -> 46199 | N34: =IF(OR(ISBLANK(task_start),ISBLANK(task_end)),"",task_end-task_start+1) -> 12
D35: =+$D$28 -> Semanal | G35: Creación detalle deuda YPF (ídem Excel) | I35: Santiago Alonso | J35: 0.5 | K35: 46192 | L35: =IF(F35="",WORKDAY(L33,5),F35) -> 46206 | N35: =IF(OR(ISBLANK(task_start),ISBLANK(task_end)),"",task_end-task_start+1) -> 15
A36: Bloque de título fase de ejemplo | G36: 5- Tablero Control General - Op. Complejas | J36: =+AVERAGE(J46:J56) -> 0.16666667 | K36: =+$K$7 -> Días Transcurridos= | L36: =+TODAY()-MIN($K$37:$K$47)-139 -> 61
C37: No llegué por nuevas solicitudes: Tablero Forecast + Reuniones por tarifas YPF + Contratos SF | D37: Semanal | E37: 1 | F37: 46185 | G37: Planilla Activos Unificados - Estandarizar + Procedimiento | I37: Santiago Alonso | J37: 0.2 | K37: 45992 | L37: =IF(F37="",WORKDAY(L36,5),F37) -> 46185 | N37: =IF(OR(ISBLANK(task_start),ISBLANK(task_end)),"",task_end-task_start+1) -> 194
A38: Las filas de la 10 a la 13 repiten el patrón de la fila 9. Repita las instrucciones de la celda A9 para todas las filas de tareas en esta hoja de cálculo. Sobrescriba los datos de ejemplo. Un ejemplo de otra fase empieza en la celda A14. Continue escribiendo tareas en las celdas de la A10 a la A13 o vaya a la celda A14 para obtener más información. | D38: =+$D$37 -> Semanal | E38: 1 | F38: 46185 | G38: Planilla DTM Estandarizada+ Procedimiento | I38: Santiago Alonso | J38: 0.9 | K38: 46023 | L38: =IF(F38="",WORKDAY(L37,5),F38) -> 46185 | N38: =IF(OR(ISBLANK(task_start),ISBLANK(task_end)),"",task_end-task_start+1) -> 163
D39: =+$D$37 -> Semanal | E39: 1 | F39: 46185 | G39: Planilla Aeroevaciaciones + Procedimiento | I39: Santiago Alonso | J39: 0.95 | K39: 45992 | L39: =IF(F39="",WORKDAY(L38,5),F39) -> 46185 | N39: =IF(OR(ISBLANK(task_start),ISBLANK(task_end)),"",task_end-task_start+1) -> 194
D40: =+$D$37 -> Semanal | E40: 1 | F40: 46185 | G40: Resumen Clientes Petróleo | I40: Santiago Alonso | J40: 0.7 | K40: 46357 | L40: =IF(F40="",WORKDAY(L39,5),F40) -> 46185 | N40: =IF(OR(ISBLANK(task_start),ISBLANK(task_end)),"",task_end-task_start+1) -> -171
...

Sheet Proyecto Datos (Actual)
A1: Cree una programación para un proyecto en esta hoja de cálculo. Escriba el título de este proyecto en la celda B1. Para obtener información sobre cómo usar esta hoja de cálculo, incluidas las instrucciones para lectores de pantalla y el nombre del autor de este libro, vea la hoja de cálculo Información. Desplácese hacia abajo por la columna A para escuchar más instrucciones. | B1: Proyecto Datos Op. Complejas
A2: Escriba el nombre de la compañía en la celda B2. | B2: IHSA S.A.
A3: Escriba el nombre del responsable del proyecto en la celda B3. Escriba la fecha de comienzo del proyecto en la celda E3. Inicio del proyecto: la etiqueta se encuentra en la celda C3. | B3: Santiago Alonso | C3: Inicio del proyecto: | E3: 45958
A4: La semana que se muestra en la celda E4 representa la semana inicial para mostrar en la programación del proyecto en la celda I4. La fecha de inicio del proyecto se considera la semana 1. Para cambiar semana que se muestra, simplemente escriba un número de semana nuevo en la celda E4. La fecha de inicio de cada semana, comenzando por la semana mostrada en la celda E4, comienza en la celda I4 y se calcula automáticamente. Hay 8 semanas representadas en esta vista desde la celda I4 hasta la celda BF4. No debería modificar estas celdas. La etiqueta de la semana para mostrar se encuentra en la celda C4. | C4: Semana para mostrar: | E4: 25 | I4: =I5 -> 46125 | P4: =P5 -> 46132 | W4: =W5 -> 46139 | AD4: =AD5 -> 46146 | AK4: =AK5 -> 46153 | AR4: =AR5 -> 46160 | AY4: =AY5 -> 46167 | BF4: =BF5 -> 46174
A5: Las celdas I5 a BL5 contienen el número de días de la semana representado en el bloque de celdas encima de cada celda de fecha y se calculan automáticamente. No debería modificar estas celdas. La fecha actual está rodeada con una línea roja (hex. AD3815) desde la fecha actual en la fila 5 hasta toda la columna de fechas y el fin de la programación del proyecto. | I5: =Inicio_del_proyecto-WEEKDAY(Inicio_del_proyecto,1)+2+7*(Semana_para_mostrar-1) -> 46125 | J5: =I5+1 -> 46126 | K5: =J5+1 -> 46127 | L5: =K5+1 -> 46128 | M5: =L5+1 -> 46129 | N5: =M5+1 -> 46130 | O5: =N5+1 -> 46131 | P5: =O5+1 -> 46132 | Q5: =P5+1 -> 46133 | ... BL5: =BK5+1 -> 46180
A6: Esta fila contiene los encabezados de la programación del proyecto posterior debajo de estos. Navegue desde la celda B6 a BL 6 para escuchar el contenido. La primera letra de cada día de la semana de la fecha encima de ese encabezado empieza en la celda I6 y continúa hasta la celda BL6. Todo el gráficos de escala de tiempo del proyecto está generados automáticamente en función de las fechas de inicio y finalización especificadas, con formatos condicionales. No modifique el contenido de las celdas en las columnas después de la columna I comenzando por la celda I7. | B6: TAREA | C6: ASIGNADO A | D6: PROGRESO | E6: INICIO | F6: FIN | H6: DÍAS | I6: =LEFT(TEXT(I5,"ddd"),1) -> l | J6: =LEFT(TEXT(J5,"ddd"),1) -> m | K6: =LEFT(TEXT(K5,"ddd"),1) -> m | L6: =LEFT(TEXT(L5,"ddd"),1) -> j | M6: =LEFT(TEXT(M5,"ddd"),1) -> v | N6: =LEFT(TEXT(N5,"ddd"),1) -> s | O6: =LEFT(TEXT(O5,"ddd"),1) -> d | P6: =LEFT(TEXT(P5,"ddd"),1) -> l | ... BL6: =LEFT(TEXT(BL5,"ddd"),1) -> d
A7: No elimine esta fila. Esta fila está oculta para conservar una fórmula que se usa para resaltar el día actual dentro de la programación del proyecto. | H7: =IF(OR(ISBLANK(task_start),ISBLANK(task_end)),"",task_end-task_start+1)
A8: La celda B8 contiene el título de ejemplo de la Fase 1. Escriba un nuevo título en la celda B8. Escriba un nombre para asignar la fase, si se aplica para el proyecto, en la celda C8. Escriba el progreso de la fase completa, si se aplica para el proyecto, en la celda D8. Escriba las fechas de inicio y finalización de la fase completa, si se aplica para el proyecto, en las celdas E8 y F8. El gráfico de Gantt rellena automáticamente las fechas adecuadas y aplica un sombreado según el progreso especificado. Para eliminar la fase y trabajar solo con las tareas, elimine esta fila. | B8: 1- Automatización de Tareas | D8: =+AVERAGE(D9:D15) -> 0.26428571 | F8: =+F15-E11+1 -> 212
A9: La celda B9 contiene la tarea de ejemplo "Tarea 1". Escriba un nuevo nombre de tarea en la celda B9. Escriba una persona a la que asignar la tarea en la celda C9. Escriba el progreso de la tarea en la celda D9. Aparece una barra de progreso en la celda y se sombrea según el número de la celda. Por ejemplo, un progreso del 50 por ciento aplicaría sombreado a la mitad de la celda. Escriba la fecha de inicio de la tarea en la celda E9. Escriba la fecha de finalización de la tarea en la celda F9. Aparece una barra de estado con sombreado para las fechas especificadas en bloques comenzando desde la celda I9 hasta la BL9. | B9: Carpeta almacenamiento en Sharepoint p/ Datalake | C9: Julio Tinelli | D9: 0.9 | E9: =Inicio_del_proyecto -> 45958 | F9: 46173 | H9: =IF(OR(ISBLANK(task_start),ISBLANK(task_end)),"",task_end-task_start+1) -> 216
A10: La celda B9 contiene la tarea de ejemplo "Tarea 1". Escriba un nuevo nombre de tarea en la celda B9. Escriba una persona a la que asignar la tarea en la celda C9. Escriba el progreso de la tarea en la celda D9. Aparece una barra de progreso en la celda y se sombrea según el número de la celda. Por ejemplo, un progreso del 50 por ciento aplicaría sombreado a la mitad de la celda. Escriba la fecha de inicio de la tarea en la celda E9. Escriba la fecha de finalización de la tarea en la celda F9. Aparece una barra de estado con sombreado para las fechas especificadas en bloques comenzando desde la celda I9 hasta la BL9. | B10: Polinómicas + Tarifario + Ev. Parámetros Precios | C10: Santiago Alonso | D10: 0.7 | E10: 45962 | F10: 46203 | H10: =IF(OR(ISBLANK(task_start),ISBLANK(task_end)),"",task_end-task_start+1) -> 242
B11: Obtener información detallada de DTM x Service Desk | C11: Santiago Alonso | D11: 0.25 | E11: 46023 | F11: 46203
B12: Días en Calle Calculado | C12: Santiago Alonso | D12: 0 | E12: =+F11+1 -> 46204 | F12: 46295 | H12: =IF(OR(ISBLANK(task_start),ISBLANK(task_end)),"",task_end-task_start+1) -> 92
B13: Aging Calculado | C13: Santiago Alonso | D13: 0 | E13: =+F12+1 -> 46296 | F13: =+WORKDAY(E13,4) -> 46302 | H13: =IF(OR(ISBLANK(task_start),ISBLANK(task_end)),"",task_end-task_start+1) -> 7
B14: Automatización de Provisión | C14: Santiago Alonso | D14: 0 | E14: =+F13+1 -> 46303 | F14: =+WORKDAY(E14,7) -> 46314
B15: Automatización de Certificaciones Mensuales | C15: Santiago Alonso | D15: 0 | E15: 46160 | F15: 46234
A16: La celda a la derecha contiene el título de ejemplo de la Fase 2. Puede crear una nueva fase en cualquier momento en la columna B. Esta programación de proyecto no necesita fases. Para quitar la fase, basta con eliminar la fila. Para crear un bloque de fase nuevo en esta fila, escriba un nuevo título en la celda a la derecha. Para continuar agregando tareas a la fase anterior, escriba una nueva fila encima de esta y rellene los datos de la tarea como se explica en la celda A9. Actualice los detalles de la fase en la celda a la derecha como se explica en la celda A8. Continúe navegando por las celdas de la columna A para obtener más información. Si no ha agregado nuevas filas en esta hoja de cálculo, verá que se han creado automáticamente 2 bloques de fase de ejemplo adicionales en las celdas B20 y B26. En caso contrario, desplácese por las celdas de la columna A para buscar los bloques adicionales. Repita las instrucciones de las celdas A8 y A9 cuando lo necesite. | B16: 2- Cotizador Automático (Neuquén) | D16: =+AVERAGE(D17:D24) -> 0.41875 | F16: =+F24-E17+1 -> 36
B17: Crear estructura de Cotizador en base a modelo armado (migra a CLAUDE) | C17: Santiago Alonso | D17: 0.9 | E17: 45958 | F17: 46173 | H17: =IF(OR(ISBLANK(task_start),ISBLANK(task_end)),"",task_end-task_start+1) -> 216
B18: Automatización Archivo Sueldos FATSA (PENDIENTE REVISIÓN GENERAL) | C18: Santiago Alonso | D18: 0.85 | E18: 45958 | F18: 45991 | H18: =IF(OR(ISBLANK(task_start),ISBLANK(task_end)),"",task_end-task_start+1) -> 34
B19: Automatización Archivo Sueldos Petro (PENDIENTE REVISIÓN GENERAL) | C19: Santiago Alonso | D19: 0.9 | E19: 45978 | F19: =+WORKDAY(E19,2) -> 45980 | H19: =IF(OR(ISBLANK(task_start),ISBLANK(task_end)),"",task_end-task_start+1) -> 3
B20: Estandarización cotizaciones COMPRAS (costos x provincia) | C20: Santiago Alonso | D20: 0.2 | E20: 45959 | F20: =+WORKDAY(E20,10) -> 45973 | H20: =IF(OR(ISBLANK(task_start),ISBLANK(task_end)),"",task_end-task_start+1) -> 15
B21: Asociar Archivo Móviles y Tráilers (Nico Sifuentes) | C21: Santiago Alonso | D21: 0.5 | E21: 45992 | F21: 46000 | H21: =IF(OR(ISBLANK(task_start),ISBLANK(task_end)),"",task_end-task_start+1) -> 9
B22: Asociar Gastos de Estructura (% de incidencia) --> Pedir a Fran | C22: Santiago Alonso | D22: 0 | E22: =+F20+1 -> 45974 | F22: =+WORKDAY(E22,4) -> 45980 | H22: =IF(OR(ISBLANK(task_start),ISBLANK(task_end)),"",task_end-task_start+1) -> 7
B23: Armado de solicitudes extra x Módulos (Ej: Med. Laboral) | C23: Santiago Alonso | D23: 0 | E23: =+F19+1 -> 45981 | F23: =+WORKDAY(E23,3) -> 45986 | H23: =IF(OR(ISBLANK(task_start),ISBLANK(task_end)),"",task_end-task_start+1) -> 6
B24: Diseño de Dashboard | C24: Santiago Alonso | D24: 0 | E24: =+F23+1 -> 45987 | F24: =+WORKDAY(E24,4) -> 45993 | H24: =IF(OR(ISBLANK(task_start),ISBLANK(task_end)),"",task_end-task_start+1) -> 7
A25: Bloque de título fase de ejemplo | B25: 3- Planilla de Control | D25: =+AVERAGE(D26:D41) -> 0.394375 | F25: =+F41-E26+1 -> 74
B26: Planilla Activos Unificados (Nico Sifuentes) - Estandarizar | C26: Santiago Alonso | D26: 0 | E26: 45962 | F26: =+WORKDAY(E26,4) -> 45967 | H26: =IF(OR(ISBLANK(task_start),ISBLANK(task_end)),"",task_end-task_start+1) -> 6
A27: Las filas de la 10 a la 13 repiten el patrón de la fila 9. Repita las instrucciones de la celda A9 para todas las filas de tareas en esta hoja de cálculo. Sobrescriba los datos de ejemplo. Un ejemplo de otra fase empieza en la celda A14. Continue escribiendo tareas en las celdas de la A10 a la A13 o vaya a la celda A14 para obtener más información. | B27: Planilla DTM Estandarizada | C27: Santiago Alonso | D27: 0.9 | E27: =+F26 -> 45967 | F27: =+WORKDAY(E27,0) -> 45967 | H27: =IF(OR(ISBLANK(task_start),ISBLANK(task_end)),"",task_end-task_start+1) -> 1
B28: Planilla Aeroevaciaciones | C28: Santiago Alonso | D28: 0.9 | E28: =+F27+0 -> 45967 | F28: =+WORKDAY(E28,0) -> 45967 | H28: =IF(OR(ISBLANK(task_start),ISBLANK(task_end)),"",task_end-task_start+1) -> 1
B29: Resumen Clientes Petróleo | C29: Santiago Alonso | D29: 0.7 | E29: =+F26+1 -> 45968 | F29: =+WORKDAY(E29,3) -> 45973 | H29: =IF(OR(ISBLANK(task_start),ISBLANK(task_end)),"",task_end-task_start+1) -> 6
B30: Resumen Clientes Minería | C30: Santiago Alonso | D30: 0.2 | E30: =+F29+1 -> 45974 | F30: =+WORKDAY(E30,3) -> 45979 | H30: =IF(OR(ISBLANK(task_start),ISBLANK(task_end)),"",task_end-task_start+1) -> 6
B31: Resumen Clientes Op. Dedicadas | C31: Santiago Alonso | D31: 0.01 | E31: =+F30+1 -> 45980 | F31: =+WORKDAY(E31,1) -> 45981 | H31: =IF(OR(ISBLANK(task_start),ISBLANK(task_end)),"",task_end-task_start+1) -> 2
B32: Días en Calle (Sharepoint --> Excel) | C32: Santiago Alonso | D32: 0.5 | E32: =+F31+1 -> 45982 | F32: =+WORKDAY(E32,3) -> 45987 | H32: =IF(OR(ISBLANK(task_start),ISBLANK(task_end)),"",task_end-task_start+1) -> 6
B33: Aging (Sharepoint --> Excel) | C33: Santiago Alonso | D33: 0.5 | E33: =+F32+1 -> 45988 | F33: =+WORKDAY(E33,3) -> 45993 | H33: =IF(OR(ISBLANK(task_start),ISBLANK(task_end)),"",task_end-task_start+1) -> 6
B34: Importe Provisionado (Datalake --> Clik Sense "Venta Bruta") | C34: Santiago Alonso | D34: 0.5 | E34: =+F33+1 -> 45994 | F34: =+WORKDAY(E34,3) -> 45999 | H34: =IF(OR(ISBLANK(task_start),ISBLANK(task_end)),"",task_end-task_start+1) -> 6
B35: Importe Facturado (Datalake --> Clik Sense "Venta Bruta") | C35: Santiago Alonso | D35: 0.5 | E35: =+F34+1 -> 46000 | F35: =+WORKDAY(E35,3) -> 46003 | H35: =IF(OR(ISBLANK(task_start),ISBLANK(task_end)),"",task_end-task_start+1) -> 4
B36: Importe Pendiente Fc (Provisión) | C36: Santiago Alonso | D36: 0.8 | E36: =+F35+1 -> 46004 | F36: =+WORKDAY(E36,2) -> 46007 | H36: =IF(OR(ISBLANK(task_start),ISBLANK(task_end)),"",task_end-task_start+1) -> 4
B37: Locaciones Geográficas Pozos Petro (ver datos Secretaria de Energía) | C37: Santiago Alonso | D37: 0.1 | E37: =+F36+1 -> 46008 | F37: =+WORKDAY(E37,3) -> 46013
B38: Locaciones Geográficas Minería | C38: Santiago Alonso | D38: 0 | E38: =+F37+1 -> 46014 | F38: =+WORKDAY(E38,3) -> 46017
B39: Locaciones Geográficas Op. Dedicadas | C39: Santiago Alonso | D39: 0 | E39: =+F38+1 -> 46018 | F39: =+WORKDAY(E39,3) -> 46022
B40: Detalle Responsables (Comerciales + Analistas) | C40: Santiago Alonso | D40: 0.5 | E40: =+F39+1 -> 46023 | F40: =+WORKDAY(E40,1) -> 46024
...

Sheet Proyecto Datos
A1: Cree una programación para un proyecto en esta hoja de cálculo. Escriba el título de este proyecto en la celda B1. Para obtener información sobre cómo usar esta hoja de cálculo, incluidas las instrucciones para lectores de pantalla y el nombre del autor de este libro, vea la hoja de cálculo Información. Desplácese hacia abajo por la columna A para escuchar más instrucciones. | B1: Proyecto Datos Op. Complejas
A2: Escriba el nombre de la compañía en la celda B2. | B2: IHSA S.A.
A3: Escriba el nombre del responsable del proyecto en la celda B3. Escriba la fecha de comienzo del proyecto en la celda E3. Inicio del proyecto: la etiqueta se encuentra en la celda C3. | B3: Santiago Alonso | C3: Inicio del proyecto: | E3: 45958
A4: La semana que se muestra en la celda E4 representa la semana inicial para mostrar en la programación del proyecto en la celda I4. La fecha de inicio del proyecto se considera la semana 1. Para cambiar semana que se muestra, simplemente escriba un número de semana nuevo en la celda E4. La fecha de inicio de cada semana, comenzando por la semana mostrada en la celda E4, comienza en la celda I4 y se calcula automáticamente. Hay 8 semanas representadas en esta vista desde la celda I4 hasta la celda BF4. No debería modificar estas celdas. La etiqueta de la semana para mostrar se encuentra en la celda C4. | C4: Semana para mostrar: | E4: 1 | I4: =I5 -> 45957 | P4: =P5 -> 45964 | W4: =W5 -> 45971 | AD4: =AD5 -> 45978 | AK4: =AK5 -> 45985 | AR4: =AR5 -> 45992 | AY4: =AY5 -> 45999 | BF4: =BF5 -> 46006
A5: Las celdas I5 a BL5 contienen el número de días de la semana representado en el bloque de celdas encima de cada celda de fecha y se calculan automáticamente. No debería modificar estas celdas. La fecha actual está rodeada con una línea roja (hex. AD3815) desde la fecha actual en la fila 5 hasta toda la columna de fechas y el fin de la programación del proyecto. | I5: =Inicio_del_proyecto-WEEKDAY(Inicio_del_proyecto,1)+2+7*(Semana_para_mostrar-1) -> 45957 | J5: =I5+1 -> 45958 | K5: =J5+1 -> 45959 | L5: =K5+1 -> 45960 | M5: =L5+1 -> 45961 | N5: =M5+1 -> 45962 | O5: =N5+1 -> 45963 | P5: =O5+1 -> 45964 | Q5: =P5+1 -> 45965 | ... BL5: =BK5+1 -> 46012
A6: Esta fila contiene los encabezados de la programación del proyecto posterior debajo de estos. Navegue desde la celda B6 a BL 6 para escuchar el contenido. La primera letra de cada día de la semana de la fecha encima de ese encabezado empieza en la celda I6 y continúa hasta la celda BL6. Todo el gráficos de escala de tiempo del proyecto está generados automáticamente en función de las fechas de inicio y finalización especificadas, con formatos condicionales. No modifique el contenido de las celdas en las columnas después de la columna I comenzando por la celda I7. | B6: TAREA | C6: ASIGNADO A | D6: PROGRESO | E6: INICIO | F6: FIN | H6: DÍAS | I6: =LEFT(TEXT(I5,"ddd"),1) -> l | J6: =LEFT(TEXT(J5,"ddd"),1) -> m | K6: =LEFT(TEXT(K5,"ddd"),1) -> m | L6: =LEFT(TEXT(L5,"ddd"),1) -> j | M6: =LEFT(TEXT(M5,"ddd"),1) -> v | N6: =LEFT(TEXT(N5,"ddd"),1) -> s | O6: =LEFT(TEXT(O5,"ddd"),1) -> d | P6: =LEFT(TEXT(P5,"ddd"),1) -> l | ... BL6: =LEFT(TEXT(BL5,"ddd"),1) -> d
A7: No elimine esta fila. Esta fila está oculta para conservar una fórmula que se usa para resaltar el día actual dentro de la programación del proyecto. | H7: =IF(OR(ISBLANK(task_start),ISBLANK(task_end)),"",task_end-task_start+1)
A8: La celda B8 contiene el título de ejemplo de la Fase 1. Escriba un nuevo título en la celda B8. Escriba un nombre para asignar la fase, si se aplica para el proyecto, en la celda C8. Escriba el progreso de la fase completa, si se aplica para el proyecto, en la celda D8. Escriba las fechas de inicio y finalización de la fase completa, si se aplica para el proyecto, en las celdas E8 y F8. El gráfico de Gantt rellena automáticamente las fechas adecuadas y aplica un sombreado según el progreso especificado. Para eliminar la fase y trabajar solo con las tareas, elimine esta fila. | B8: 1- Automatización de Tareas | D8: =+AVERAGE(D9:D15) -> 0.16428571 | F8: =+F15-E11+1 -> 48
A9: La celda B9 contiene la tarea de ejemplo "Tarea 1". Escriba un nuevo nombre de tarea en la celda B9. Escriba una persona a la que asignar la tarea en la celda C9. Escriba el progreso de la tarea en la celda D9. Aparece una barra de progreso en la celda y se sombrea según el número de la celda. Por ejemplo, un progreso del 50 por ciento aplicaría sombreado a la mitad de la celda. Escriba la fecha de inicio de la tarea en la celda E9. Escriba la fecha de finalización de la tarea en la celda F9. Aparece una barra de estado con sombreado para las fechas especificadas en bloques comenzando desde la celda I9 hasta la BL9. | B9: Carpeta almacenamiento en Sharepoint p/ Datalake | C9: Julio Tinelli | D9: 0.2 | E9: =Inicio_del_proyecto -> 45958 | F9: =+WORKDAY(E9,10) -> 45972 | H9: =IF(OR(ISBLANK(task_start),ISBLANK(task_end)),"",task_end-task_start+1) -> 15
A10: La celda B9 contiene la tarea de ejemplo "Tarea 1". Escriba un nuevo nombre de tarea en la celda B9. Escriba una persona a la que asignar la tarea en la celda C9. Escriba el progreso de la tarea en la celda D9. Aparece una barra de progreso en la celda y se sombrea según el número de la celda. Por ejemplo, un progreso del 50 por ciento aplicaría sombreado a la mitad de la celda. Escriba la fecha de inicio de la tarea en la celda E9. Escriba la fecha de finalización de la tarea en la celda F9. Aparece una barra de estado con sombreado para las fechas especificadas en bloques comenzando desde la celda I9 hasta la BL9. | B10: Polinómicas + Tarifario + Ev. Parámetros Precios | C10: Santiago Alonso | D10: 0.7 | E10: 45962 | F10: =+WORKDAY(E10,2) -> 45965 | H10: =IF(OR(ISBLANK(task_start),ISBLANK(task_end)),"",task_end-task_start+1) -> 4
B11: Obtener información detallada de DTM x Service Desk | C11: Santiago Alonso | D11: 0.25 | E11: 46023 | F11: =+WORKDAY(E11,7) -> 46034
B12: Días en Calle Calculado | C12: Santiago Alonso | D12: 0 | E12: =+F11+1 -> 46035 | F12: =+WORKDAY(E12,4) -> 46041 | H12: =IF(OR(ISBLANK(task_start),ISBLANK(task_end)),"",task_end-task_start+1) -> 7
B13: Aging Calculado | C13: Santiago Alonso | D13: 0 | E13: =+F12+1 -> 46042 | F13: =+WORKDAY(E13,4) -> 46048 | H13: =IF(OR(ISBLANK(task_start),ISBLANK(task_end)),"",task_end-task_start+1) -> 7
B14: Automatización de Provisión | C14: Santiago Alonso | D14: 0 | E14: =+F13+1 -> 46049 | F14: =+WORKDAY(E14,7) -> 46058
B15: Automatización de Certificaciones Mensuales | C15: Santiago Alonso | D15: 0 | E15: =+F14+1 -> 46059 | F15: =+WORKDAY(E15,7) -> 46070
A16: La celda a la derecha contiene el título de ejemplo de la Fase 2. Puede crear una nueva fase en cualquier momento en la columna B. Esta programación de proyecto no necesita fases. Para quitar la fase, basta con eliminar la fila. Para crear un bloque de fase nuevo en esta fila, escriba un nuevo título en la celda a la derecha. Para continuar agregando tareas a la fase anterior, escriba una nueva fila encima de esta y rellene los datos de la tarea como se explica en la celda A9. Actualice los detalles de la fase en la celda a la derecha como se explica en la celda A8. Continúe navegando por las celdas de la columna A para obtener más información. Si no ha agregado nuevas filas en esta hoja de cálculo, verá que se han creado automáticamente 2 bloques de fase de ejemplo adicionales en las celdas B20 y B26. En caso contrario, desplácese por las celdas de la columna A para buscar los bloques adicionales. Repita las instrucciones de las celdas A8 y A9 cuando lo necesite. | B16: 2- Cotizador Automático (Neuquén) | D16: =+AVERAGE(D17:D23) -> 0.028571429 | F16: =+F23-E17+1 -> 36
B17: Crear estructura de Cotizador en base a modelo armado | C17: Santiago Alonso | D17: 0 | E17: 45958 | F17: =+WORKDAY(E17,60) -> 46042 | H17: =IF(OR(ISBLANK(task_start),ISBLANK(task_end)),"",task_end-task_start+1) -> 85
B18: Automatización Archivo Sueldos FATSA | C18: Santiago Alonso | D18: 0 | E18: 45978 | F18: =+WORKDAY(E18,2) -> 45980 | H18: =IF(OR(ISBLANK(task_start),ISBLANK(task_end)),"",task_end-task_start+1) -> 3
B19: Automatización Archivo Sueldos Petro | C19: Santiago Alonso | D19: 0 | E19: 45978 | F19: =+WORKDAY(E19,2) -> 45980 | H19: =IF(OR(ISBLANK(task_start),ISBLANK(task_end)),"",task_end-task_start+1) -> 3
B20: Estandarización cotizaciones COMPRAS | C20: Santiago Alonso | D20: 0.2 | E20: 45959 | F20: =+WORKDAY(E20,10) -> 45973 | H20: =IF(OR(ISBLANK(task_start),ISBLANK(task_end)),"",task_end-task_start+1) -> 15
B21: Asociar Gastos de Estructura (% de incidencia) | C21: Santiago Alonso | D21: 0 | E21: =+F20+1 -> 45974 | F21: =+WORKDAY(E21,4) -> 45980 | H21: =IF(OR(ISBLANK(task_start),ISBLANK(task_end)),"",task_end-task_start+1) -> 7
B22: Armado de solicitudes extra x Módulos (Ej: Med. Laboral) | C22: Santiago Alonso | D22: 0 | E22: =+F19+1 -> 45981 | F22: =+WORKDAY(E22,3) -> 45986 | H22: =IF(OR(ISBLANK(task_start),ISBLANK(task_end)),"",task_end-task_start+1) -> 6
B23: Diseño de Dashboard | C23: Santiago Alonso | D23: 0 | E23: =+F22+1 -> 45987 | F23: =+WORKDAY(E23,4) -> 45993 | H23: =IF(OR(ISBLANK(task_start),ISBLANK(task_end)),"",task_end-task_start+1) -> 7
A24: Bloque de título fase de ejemplo | B24: 3- Planilla de Control | D24: =+AVERAGE(D25:D40) -> 0.394375 | F24: =+F40-E25+1 -> 74
B25: Planilla Activos Unificados (Nico Sifuentes) - Estandarizar | C25: Santiago Alonso | D25: 0 | E25: 45962 | F25: =+WORKDAY(E25,4) -> 45967 | H25: =IF(OR(ISBLANK(task_start),ISBLANK(task_end)),"",task_end-task_start+1) -> 6
A26: Las filas de la 10 a la 13 repiten el patrón de la fila 9. Repita las instrucciones de la celda A9 para todas las filas de tareas en esta hoja de cálculo. Sobrescriba los datos de ejemplo. Un ejemplo de otra fase empieza en la celda A14. Continue escribiendo tareas en las celdas de la A10 a la A13 o vaya a la celda A14 para obtener más información. | B26: Planilla DTM Estandarizada | C26: Santiago Alonso | D26: 0.9 | E26: =+F25 -> 45967 | F26: =+WORKDAY(E26,0) -> 45967 | H26: =IF(OR(ISBLANK(task_start),ISBLANK(task_end)),"",task_end-task_start+1) -> 1
B27: Planilla Aeroevaciaciones | C27: Santiago Alonso | D27: 0.9 | E27: =+F26+0 -> 45967 | F27: =+WORKDAY(E27,0) -> 45967 | H27: =IF(OR(ISBLANK(task_start),ISBLANK(task_end)),"",task_end-task_start+1) -> 1
B28: Resumen Clientes Petróleo | C28: Santiago Alonso | D28: 0.7 | E28: =+F25+1 -> 45968 | F28: =+WORKDAY(E28,3) -> 45973 | H28: =IF(OR(ISBLANK(task_start),ISBLANK(task_end)),"",task_end-task_start+1) -> 6
B29: Resumen Clientes Minería | C29: Santiago Alonso | D29: 0.2 | E29: =+F28+1 -> 45974 | F29: =+WORKDAY(E29,3) -> 45979 | H29: =IF(OR(ISBLANK(task_start),ISBLANK(task_end)),"",task_end-task_start+1) -> 6
B30: Resumen Clientes Op. Dedicadas | C30: Santiago Alonso | D30: 0.01 | E30: =+F29+1 -> 45980 | F30: =+WORKDAY(E30,1) -> 45981 | H30: =IF(OR(ISBLANK(task_start),ISBLANK(task_end)),"",task_end-task_start+1) -> 2
B31: Días en Calle (Sharepoint --> Excel) | C31: Santiago Alonso | D31: 0.5 | E31: =+F30+1 -> 45982 | F31: =+WORKDAY(E31,3) -> 45987 | H31: =IF(OR(ISBLANK(task_start),ISBLANK(task_end)),"",task_end-task_start+1) -> 6
B32: Aging (Sharepoint --> Excel) | C32: Santiago Alonso | D32: 0.5 | E32: =+F31+1 -> 45988 | F32: =+WORKDAY(E32,3) -> 45993 | H32: =IF(OR(ISBLANK(task_start),ISBLANK(task_end)),"",task_end-task_start+1) -> 6
B33: Importe Provisionado (Datalake --> Clik Sense "Venta Bruta") | C33: Santiago Alonso | D33: 0.5 | E33: =+F32+1 -> 45994 | F33: =+WORKDAY(E33,3) -> 45999 | H33: =IF(OR(ISBLANK(task_start),ISBLANK(task_end)),"",task_end-task_start+1) -> 6
B34: Importe Facturado (Datalake --> Clik Sense "Venta Bruta") | C34: Santiago Alonso | D34: 0.5 | E34: =+F33+1 -> 46000 | F34: =+WORKDAY(E34,3) -> 46003 | H34: =IF(OR(ISBLANK(task_start),ISBLANK(task_end)),"",task_end-task_start+1) -> 4
B35: Importe Pendiente Fc (Provisión) | C35: Santiago Alonso | D35: 0.8 | E35: =+F34+1 -> 46004 | F35: =+WORKDAY(E35,2) -> 46007 | H35: =IF(OR(ISBLANK(task_start),ISBLANK(task_end)),"",task_end-task_start+1) -> 4
B36: Locaciones Geográficas Pozos Petro (ver datos Secretaria de Energía) | C36: Santiago Alonso | D36: 0.1 | E36: =+F35+1 -> 46008 | F36: =+WORKDAY(E36,3) -> 46013
B37: Locaciones Geográficas Minería | C37: Santiago Alonso | D37: 0 | E37: =+F36+1 -> 46014 | F37: =+WORKDAY(E37,3) -> 46017
B38: Locaciones Geográficas Op. Dedicadas | C38: Santiago Alonso | D38: 0 | E38: =+F37+1 -> 46018 | F38: =+WORKDAY(E38,3) -> 46022
B39: Detalle Responsables (Comerciales + Analistas) | C39: Santiago Alonso | D39: 0.5 | E39: =+F38+1 -> 46023 | F39: =+WORKDAY(E39,1) -> 46024
B40: Armado de Dashboard + Diseño | C40: Santiago Alonso | D40: 0.2 | E40: =+F39+1 -> 46025 | F40: =+WORKDAY(E40,7) -> 46035 | H40: =IF(OR(ISBLANK(task_start),ISBLANK(task_end)),"",task_end-task_start+1) -> 11
...

Sheet Acerca de
A2: GRÁFICO GANTT SIMPLE de Vertex42.com
A3: https://www.vertex42.com/ExcelTemplates/simple-gantt-chart.html
A4: Información sobre esta plantilla
A5: Esta plantilla proporciona una forma sencilla de crear un diagrama de Gantt para ayudarle a visualizar su proyecto y realizar un seguimiento de este. Simplemente escriba sus tareas y fechas de inicio y finalización, no necesita fórmulas. Las barras del gráfico de Gantt representan la duración de la tarea y se muestran con formato condicional. Para insertar nuevas tareas, inserte filas nuevas.
A6: Guía para lectores de pantalla
A7: Hay 2 hojas de cálculo en este libro. ParteDeHoras Información Las instrucciones de las hojas de cálculo se encuentran en la columna A de cada hoja, a partir de la celda A1. Están escritas con texto oculto. Cada paso le guiará a través de la información de esa fila. Los pasos posteriores continúan en la celda A2, A3, y así sucesivamente, a menos que se indique de forma explícita. Por ejemplo, el texto de una instrucción podría ser “Vaya a la celda A6” para continuar con el siguiente paso. Este texto oculto no se imprimirá. Para quitar las instrucciones de la hoja de cálculo, es suficiente con eliminar la columna A.
A8: Ayuda adicional
A9: Haga clic en el vínculo siguiente para visitar vertex42.com y obtener más información sobre cómo usar esta plantilla, como la forma de calcular los días laborales, crear dependencias de tareas, cambiar los colores de las barras, agregar una barra de desplazamiento para que sea más fácil cambiar la semana que se muestra, ampliar el intervalo de fechas que se muestran en el gráfico, etcétera.
A10: Cómo usar el gráfico de Gantt simple
A11: Más plantillas de administración de proyectos
A12: Visite Vertex42.com para descargar otras plantillas de administración de proyectos, como distintas programaciones de proyectos, diagramas de Gantt, listas de tareas, etcétera.
A13: Plantillas de administración de proyectos
... A16: Las empresas encontrarán plantillas de facturas, partes de horas, informes financieros, planificación de proyectos y plantillas para hacer un seguimiento del inventario. Los profesores y los estudiantes encontrarán recursos como programaciones de clases, libros de calificaciones y hojas de asistencia. Organice su vida familiar con planificadores de comidas, listas y registros de ejercicio. Cada plantilla ha sido cuidadosamente diseñada, perfeccionada y mejorada a lo largo del tiempo gracias a los comentarios de miles de usuarios.

Sheet Tablero
B1: TABLERO EJECUTIVO — PROYECTO DATOS OP. COMPLEJAS
B2: ="IHSA S.A. · Responsable: "&'Proyecto Datos (OKR´s)'!$G$3&" · Inicio: "&TEXT('Proyecto Datos (OKR´s)'!$K$3,"dd/mm/yyyy")&" · Actualizado al "&TEXT(TODAY(),"dd/mm/yyyy") -> IHSA S.A. · Responsable: Santiago Alonso · Inicio: 28/10/2025 · Actualizado al 19/06/2026
B4: Avance Global | D4: Tareas | E4: Completadas | F4: En curso | G4: Próximas (≤7d) | H4: Vencidas
B5: =IFERROR(AVERAGE(_Datos!$I$7:$I$200),0) -> 0.48928571 | D5: =COUNT(_Datos!$H$7:$H$200) -> 42 | E5: =COUNTIF(_Datos!$J$7:$J$200,"Completado") -> 2 | F5: =COUNTIF(_Datos!$J$7:$J$200,"En curso") -> 13 | G5: =COUNTIF(_Datos!$J$7:$J$200,"Próximo a vencer") -> 14 | H5: =COUNTIF(_Datos!$J$7:$J$200,"Vencido") -> 13
B8: AVANCE POR MÓDULO (OKR)
B9: Módulo / Entregable | G9: Tareas | H9: % Avance | I9: Avance
B10: ='Proyecto Datos (OKR´s)'!$G$7 -> 1- GOC: Módulo de Datos para Procesos de Certificación (Inteligencia Comercial) | G10: =COUNTIF(_Datos!$D$7:$D$200,$B10) -> 1 | H10: =IFERROR(AVERAGEIF(_Datos!$D$7:$D$200,$B10,_Datos!$I$7:$I$200),"") -> 0.2 | I10: =IFERROR(AVERAGEIF(_Datos!$D$7:$D$200,$B10,_Datos!$I$7:$I$200),"") -> 0.2
B11: ='Proyecto Datos (OKR´s)'!$G$9 -> 2- Cotizador de Operaciones Complejas | G11: =COUNTIF(_Datos!$D$7:$D$200,$B11) -> 12 | H11: =IFERROR(AVERAGEIF(_Datos!$D$7:$D$200,$B11,_Datos!$I$7:$I$200),"") -> 0.48333333 | I11: =IFERROR(AVERAGEIF(_Datos!$D$7:$D$200,$B11,_Datos!$I$7:$I$200),"") -> 0.48333333
B12: ='Proyecto Datos (OKR´s)'!$G$22 -> 3- Tablero BI OPEX - Real vs BO | G12: =COUNTIF(_Datos!$D$7:$D$200,$B12) -> 4 | H12: =IFERROR(AVERAGEIF(_Datos!$D$7:$D$200,$B12,_Datos!$I$7:$I$200),"") -> 0.875 | I12: =IFERROR(AVERAGEIF(_Datos!$D$7:$D$200,$B12,_Datos!$I$7:$I$200),"") -> 0.875
B13: ='Proyecto Datos (OKR´s)'!$G$27 -> 4- Tablero BI DEUDA | G13: =COUNTIF(_Datos!$D$7:$D$200,$B13) -> 8 | H13: =IFERROR(AVERAGEIF(_Datos!$D$7:$D$200,$B13,_Datos!$I$7:$I$200),"") -> 0.725 | I13: =IFERROR(AVERAGEIF(_Datos!$D$7:$D$200,$B13,_Datos!$I$7:$I$200),"") -> 0.725
B14: ='Proyecto Datos (OKR´s)'!$G$36 -> 5- Tablero Control General - Op. Complejas | G14: =COUNTIF(_Datos!$D$7:$D$200,$B14) -> 11 | H14: =IFERROR(AVERAGEIF(_Datos!$D$7:$D$200,$B14,_Datos!$I$7:$I$200),"") -> 0.43181818 | I14: =IFERROR(AVERAGEIF(_Datos!$D$7:$D$200,$B14,_Datos!$I$7:$I$200),"") -> 0.43181818
B15: ='Proyecto Datos (OKR´s)'!$G$48 -> 6- Automatización de procesos: certificación, provisión,polinómicas | G15: =COUNTIF(_Datos!$D$7:$D$200,$B15) -> 3 | H15: =IFERROR(AVERAGEIF(_Datos!$D$7:$D$200,$B15,_Datos!$I$7:$I$200),"") -> 0.13333333 | I15: =IFERROR(AVERAGEIF(_Datos!$D$7:$D$200,$B15,_Datos!$I$7:$I$200),"") -> 0.13333333
B16: ='Proyecto Datos (OKR´s)'!$G$52 -> 7- Incorporación de Operaciones Complejas en sistemas de la compañía: Salesforce, SAP, etc. | G16: =COUNTIF(_Datos!$D$7:$D$200,$B16) -> 3 | H16: =IFERROR(AVERAGEIF(_Datos!$D$7:$D$200,$B16,_Datos!$I$7:$I$200),"") -> 0.033333333 | I16: =IFERROR(AVERAGEIF(_Datos!$D$7:$D$200,$B16,_Datos!$I$7:$I$200),"") -> 0.033333333
B19: AVANCE POR SPRINT
B20: Sprint | C20: Tareas | D20: Pendientes | E20: Vencidas | F20: Próx. a vencer | G20: Próxima entrega | H20: % Avance
B21: =IF($K21="","",IF($K21=9999,"(Sin sprint)",$K21)) -> 1 | C21: =IF($K21="","",COUNTIF(_Datos!$AD$7:$AD$200,$K21)) -> 2 | D21: =IF($K21="","",COUNTIFS(_Datos!$AD$7:$AD$200,$K21,_Datos!$J$7:$J$200,"<>Completado")) -> 0 | E21: =IF($K21="","",COUNTIFS(_Datos!$AD$7:$AD$200,$K21,_Datos!$J$7:$J$200,"Vencido")) -> 0 | F21: =IF($K21="","",COUNTIFS(_Datos!$AD$7:$AD$200,$K21,_Datos!$J$7:$J$200,"Próximo a vencer")) -> 0 | G21: =IF($K21="","",IF($D21=0,"—",_xlfn.MINIFS(_Datos!$H$7:$H$200,_Datos!$AD$7:$AD$200,$K21,_Datos!$J$7:$J$200,"<>Completado"))) -> — | H21: =IF($K21="","",IFERROR(AVERAGEIF(_Datos!$AD$7:$AD$200,$K21,_Datos!$I$7:$I$200),"")) -> 1 | K21: =IFERROR(SMALL(_Datos!$Q$7:$Q$37,ROW()-21+1),"") -> 1
B22: =IF($K22="","",IF($K22=9999,"(Sin sprint)",$K22)) -> 2 | C22: =IF($K22="","",COUNTIF(_Datos!$AD$7:$AD$200,$K22)) -> 21 | D22: =IF($K22="","",COUNTIFS(_Datos!$AD$7:$AD$200,$K22,_Datos!$J$7:$J$200,"<>Completado")) -> 21 | E22: =IF($K22="","",COUNTIFS(_Datos!$AD$7:$AD$200,$K22,_Datos!$J$7:$J$200,"Vencido")) -> 13 | F22: =IF($K22="","",COUNTIFS(_Datos!$AD$7:$AD$200,$K22,_Datos!$J$7:$J$200,"Próximo a vencer")) -> 7 | G22: =IF($K22="","",IF($D22=0,"—",_xlfn.MINIFS(_Datos!$H$7:$H$200,_Datos!$AD$7:$AD$200,$K22,_Datos!$J$7:$J$200,"<>Completado"))) -> 46185 | H22: =IF($K22="","",IFERROR(AVERAGEIF(_Datos!$AD$7:$AD$200,$K22,_Datos!$I$7:$I$200),"")) -> 0.70238095 | K22: =IFERROR(SMALL(_Datos!$Q$7:$Q$37,ROW()-21+1),"") -> 2
B23: =IF($K23="","",IF($K23=9999,"(Sin sprint)",$K23)) -> (Sin sprint) | C23: =IF($K23="","",COUNTIF(_Datos!$AD$7:$AD$200,$K23)) -> 19 | D23: =IF($K23="","",COUNTIFS(_Datos!$AD$7:$AD$200,$K23,_Datos!$J$7:$J$200,"<>Completado")) -> 19 | E23: =IF($K23="","",COUNTIFS(_Datos!$AD$7:$AD$200,$K23,_Datos!$J$7:$J$200,"Vencido")) -> 0 | F23: =IF($K23="","",COUNTIFS(_Datos!$AD$7:$AD$200,$K23,_Datos!$J$7:$J$200,"Próximo a vencer")) -> 7 | G23: =IF($K23="","",IF($D23=0,"—",_xlfn.MINIFS(_Datos!$H$7:$H$200,_Datos!$AD$7:$AD$200,$K23,_Datos!$J$7:$J$200,"<>Completado"))) -> 46192 | H23: =IF($K23="","",IFERROR(AVERAGEIF(_Datos!$AD$7:$AD$200,$K23,_Datos!$I$7:$I$200),"")) -> 0.2 | K23: =IFERROR(SMALL(_Datos!$Q$7:$Q$37,ROW()-21+1),"") -> 9999
B24: =IF($K24="","",IF($K24=9999,"(Sin sprint)",$K24)) | C24: =IF($K24="","",COUNTIF(_Datos!$AD$7:$AD$200,$K24)) | D24: =IF($K24="","",COUNTIFS(_Datos!$AD$7:$AD$200,$K24,_Datos!$J$7:$J$200,"<>Completado")) | E24: =IF($K24="","",COUNTIFS(_Datos!$AD$7:$AD$200,$K24,_Datos!$J$7:$J$200,"Vencido")) | F24: =IF($K24="","",COUNTIFS(_Datos!$AD$7:$AD$200,$K24,_Datos!$J$7:$J$200,"Próximo a vencer")) | G24: =IF($K24="","",IF($D24=0,"—",_xlfn.MINIFS(_Datos!$H$7:$H$200,_Datos!$AD$7:$AD$200,$K24,_Datos!$J$7:$J$200,"<>Completado"))) | H24: =IF($K24="","",IFERROR(AVERAGEIF(_Datos!$AD$7:$AD$200,$K24,_Datos!$I$7:$I$200),"")) | K24: =IFERROR(SMALL(_Datos!$Q$7:$Q$37,ROW()-21+1),"")
B25: =IF($K25="","",IF($K25=9999,"(Sin sprint)",$K25)) | C25: =IF($K25="","",COUNTIF(_Datos!$AD$7:$AD$200,$K25)) | D25: =IF($K25="","",COUNTIFS(_Datos!$AD$7:$AD$200,$K25,_Datos!$J$7:$J$200,"<>Completado")) | E25: =IF($K25="","",COUNTIFS(_Datos!$AD$7:$AD$200,$K25,_Datos!$J$7:$J$200,"Vencido")) | F25: =IF($K25="","",COUNTIFS(_Datos!$AD$7:$AD$200,$K25,_Datos!$J$7:$J$200,"Próximo a vencer")) | G25: =IF($K25="","",IF($D25=0,"—",_xlfn.MINIFS(_Datos!$H$7:$H$200,_Datos!$AD$7:$AD$200,$K25,_Datos!$J$7:$J$200,"<>Completado"))) | H25: =IF($K25="","",IFERROR(AVERAGEIF(_Datos!$AD$7:$AD$200,$K25,_Datos!$I$7:$I$200),"")) | K25: =IFERROR(SMALL(_Datos!$Q$7:$Q$37,ROW()-21+1),"")
B26: =IF($K26="","",IF($K26=9999,"(Sin sprint)",$K26)) | C26: =IF($K26="","",COUNTIF(_Datos!$AD$7:$AD$200,$K26)) | D26: =IF($K26="","",COUNTIFS(_Datos!$AD$7:$AD$200,$K26,_Datos!$J$7:$J$200,"<>Completado")) | E26: =IF($K26="","",COUNTIFS(_Datos!$AD$7:$AD$200,$K26,_Datos!$J$7:$J$200,"Vencido")) | F26: =IF($K26="","",COUNTIFS(_Datos!$AD$7:$AD$200,$K26,_Datos!$J$7:$J$200,"Próximo a vencer")) | G26: =IF($K26="","",IF($D26=0,"—",_xlfn.MINIFS(_Datos!$H$7:$H$200,_Datos!$AD$7:$AD$200,$K26,_Datos!$J$7:$J$200,"<>Completado"))) | H26: =IF($K26="","",IFERROR(AVERAGEIF(_Datos!$AD$7:$AD$200,$K26,_Datos!$I$7:$I$200),"")) | K26: =IFERROR(SMALL(_Datos!$Q$7:$Q$37,ROW()-21+1),"")
B27: =IF($K27="","",IF($K27=9999,"(Sin sprint)",$K27)) | C27: =IF($K27="","",COUNTIF(_Datos!$AD$7:$AD$200,$K27)) | D27: =IF($K27="","",COUNTIFS(_Datos!$AD$7:$AD$200,$K27,_Datos!$J$7:$J$200,"<>Completado")) | E27: =IF($K27="","",COUNTIFS(_Datos!$AD$7:$AD$200,$K27,_Datos!$J$7:$J$200,"Vencido")) | F27: =IF($K27="","",COUNTIFS(_Datos!$AD$7:$AD$200,$K27,_Datos!$J$7:$J$200,"Próximo a vencer")) | G27: =IF($K27="","",IF($D27=0,"—",_xlfn.MINIFS(_Datos!$H$7:$H$200,_Datos!$AD$7:$AD$200,$K27,_Datos!$J$7:$J$200,"<>Completado"))) | H27: =IF($K27="","",IFERROR(AVERAGEIF(_Datos!$AD$7:$AD$200,$K27,_Datos!$I$7:$I$200),"")) | K27: =IFERROR(SMALL(_Datos!$Q$7:$Q$37,ROW()-21+1),"")
B28: =IF($K28="","",IF($K28=9999,"(Sin sprint)",$K28)) | C28: =IF($K28="","",COUNTIF(_Datos!$AD$7:$AD$200,$K28)) | D28: =IF($K28="","",COUNTIFS(_Datos!$AD$7:$AD$200,$K28,_Datos!$J$7:$J$200,"<>Completado")) | E28: =IF($K28="","",COUNTIFS(_Datos!$AD$7:$AD$200,$K28,_Datos!$J$7:$J$200,"Vencido")) | F28: =IF($K28="","",COUNTIFS(_Datos!$AD$7:$AD$200,$K28,_Datos!$J$7:$J$200,"Próximo a vencer")) | G28: =IF($K28="","",IF($D28=0,"—",_xlfn.MINIFS(_Datos!$H$7:$H$200,_Datos!$AD$7:$AD$200,$K28,_Datos!$J$7:$J$200,"<>Completado"))) | H28: =IF($K28="","",IFERROR(AVERAGEIF(_Datos!$AD$7:$AD$200,$K28,_Datos!$I$7:$I$200),"")) | K28: =IFERROR(SMALL(_Datos!$Q$7:$Q$37,ROW()-21+1),"")
B29: =IF($K29="","",IF($K29=9999,"(Sin sprint)",$K29)) | C29: =IF($K29="","",COUNTIF(_Datos!$AD$7:$AD$200,$K29)) | D29: =IF($K29="","",COUNTIFS(_Datos!$AD$7:$AD$200,$K29,_Datos!$J$7:$J$200,"<>Completado")) | E29: =IF($K29="","",COUNTIFS(_Datos!$AD$7:$AD$200,$K29,_Datos!$J$7:$J$200,"Vencido")) | F29: =IF($K29="","",COUNTIFS(_Datos!$AD$7:$AD$200,$K29,_Datos!$J$7:$J$200,"Próximo a vencer")) | G29: =IF($K29="","",IF($D29=0,"—",_xlfn.MINIFS(_Datos!$H$7:$H$200,_Datos!$AD$7:$AD$200,$K29,_Datos!$J$7:$J$200,"<>Completado"))) | H29: =IF($K29="","",IFERROR(AVERAGEIF(_Datos!$AD$7:$AD$200,$K29,_Datos!$I$7:$I$200),"")) | K29: =IFERROR(SMALL(_Datos!$Q$7:$Q$37,ROW()-21+1),"")
B30: =IF($K30="","",IF($K30=9999,"(Sin sprint)",$K30)) | C30: =IF($K30="","",COUNTIF(_Datos!$AD$7:$AD$200,$K30)) | D30: =IF($K30="","",COUNTIFS(_Datos!$AD$7:$AD$200,$K30,_Datos!$J$7:$J$200,"<>Completado")) | E30: =IF($K30="","",COUNTIFS(_Datos!$AD$7:$AD$200,$K30,_Datos!$J$7:$J$200,"Vencido")) | F30: =IF($K30="","",COUNTIFS(_Datos!$AD$7:$AD$200,$K30,_Datos!$J$7:$J$200,"Próximo a vencer")) | G30: =IF($K30="","",IF($D30=0,"—",_xlfn.MINIFS(_Datos!$H$7:$H$200,_Datos!$AD$7:$AD$200,$K30,_Datos!$J$7:$J$200,"<>Completado"))) | H30: =IF($K30="","",IFERROR(AVERAGEIF(_Datos!$AD$7:$AD$200,$K30,_Datos!$I$7:$I$200),"")) | K30: =IFERROR(SMALL(_Datos!$Q$7:$Q$37,ROW()-21+1),"")
B31: =IF($K31="","",IF($K31=9999,"(Sin sprint)",$K31)) | C31: =IF($K31="","",COUNTIF(_Datos!$AD$7:$AD$200,$K31)) | D31: =IF($K31="","",COUNTIFS(_Datos!$AD$7:$AD$200,$K31,_Datos!$J$7:$J$200,"<>Completado")) | E31: =IF($K31="","",COUNTIFS(_Datos!$AD$7:$AD$200,$K31,_Datos!$J$7:$J$200,"Vencido")) | F31: =IF($K31="","",COUNTIFS(_Datos!$AD$7:$AD$200,$K31,_Datos!$J$7:$J$200,"Próximo a vencer")) | G31: =IF($K31="","",IF($D31=0,"—",_xlfn.MINIFS(_Datos!$H$7:$H$200,_Datos!$AD$7:$AD$200,$K31,_Datos!$J$7:$J$200,"<>Completado"))) | H31: =IF($K31="","",IFERROR(AVERAGEIF(_Datos!$AD$7:$AD$200,$K31,_Datos!$I$7:$I$200),"")) | K31: =IFERROR(SMALL(_Datos!$Q$7:$Q$37,ROW()-21+1),"")
B32: =IF($K32="","",IF($K32=9999,"(Sin sprint)",$K32)) | C32: =IF($K32="","",COUNTIF(_Datos!$AD$7:$AD$200,$K32)) | D32: =IF($K32="","",COUNTIFS(_Datos!$AD$7:$AD$200,$K32,_Datos!$J$7:$J$200,"<>Completado")) | E32: =IF($K32="","",COUNTIFS(_Datos!$AD$7:$AD$200,$K32,_Datos!$J$7:$J$200,"Vencido")) | F32: =IF($K32="","",COUNTIFS(_Datos!$AD$7:$AD$200,$K32,_Datos!$J$7:$J$200,"Próximo a vencer")) | G32: =IF($K32="","",IF($D32=0,"—",_xlfn.MINIFS(_Datos!$H$7:$H$200,_Datos!$AD$7:$AD$200,$K32,_Datos!$J$7:$J$200,"<>Completado"))) | H32: =IF($K32="","",IFERROR(AVERAGEIF(_Datos!$AD$7:$AD$200,$K32,_Datos!$I$7:$I$200),"")) | K32: =IFERROR(SMALL(_Datos!$Q$7:$Q$37,ROW()-21+1),"")
B34: ALERTAS / CUELLOS DE BOTELLA
B35: Críticas | C35: Bloqueadas | D35: Atrasadas | E35: Sobrecarga
B36: =COUNTIF(_Datos!$AB$7:$AB$200,"Crítica") -> 6 | C36: =COUNTIF(_Datos!$Z$7:$Z$200,TRUE) -> 0 | D36: =COUNTIF(_Datos!$W$7:$W$200,">0") -> 13 | E36: =COUNTIF(_Datos!$AC$7:$AC$200,"*SOBRECARGA*") -> 37
B37: Bloqueada = debía iniciar y sigue en 0%. Atrasada = pasó la fecha objetivo sin completar. Sobrecarga = responsable con >8 tareas pendientes. La lista priorizada completa está en 'Entregas Próximas'.
B39: Las métricas se recalculan solas desde la hoja Gantt. Los sprints (vigentes) aparecen automáticamente al usarse y conservan el histórico. El % por módulo se recalcula de forma independiente (no usa las celdas de promedio de las filas de fase).

Sheet Entregas Próximas
B1: ENTREGAS PRÓXIMAS — PRIORIZADAS
